<sdf version='1.6'>
  <world name='default'>
    <model name='ground_plane'>
      <static>1</static>
      <link name='link'>
        <collision name='collision'>
          <geometry>
            <plane>
              <normal>0 0 1</normal>
              <size>100 100</size>
            </plane>
          </geometry>
          <surface>
            <friction>
              <ode>
                <mu>100</mu>
                <mu2>50</mu2>
              </ode>
              <torsional>
                <ode/>
              </torsional>
            </friction>
            <contact>
              <ode/>
            </contact>
            <bounce/>
          </surface>
          <max_contacts>10</max_contacts>
        </collision>
        <visual name='visual'>
          <cast_shadows>0</cast_shadows>
          <geometry>
            <plane>
              <normal>0 0 1</normal>
              <size>100 100</size>
            </plane>
          </geometry>
          <material>
            <script>
              <uri>file://media/materials/scripts/gazebo.material</uri>
              <name>Gazebo/Grey</name>
            </script>
          </material>
        </visual>
        <self_collide>0</self_collide>
        <kinematic>0</kinematic>
        <gravity>1</gravity>
      </link>
    </model>
    <light name='sun' type='directional'>
      <cast_shadows>1</cast_shadows>
      <pose frame=''>0 0 10 0 -0 0</pose>
      <diffuse>0.8 0.8 0.8 1</diffuse>
      <specular>0.1 0.1 0.1 1</specular>
      <attenuation>
        <range>1000</range>
        <constant>0.9</constant>
        <linear>0.01</linear>
        <quadratic>0.001</quadratic>
      </attenuation>
      <direction>-0.5 0.5 -1</direction>
    </light>
    <physics name='default_physics' default='0' type='ode'>
      <real_time_update_rate>1000</real_time_update_rate>
      <max_step_size>0.001</max_step_size>
      <real_time_factor>1</real_time_factor>
    </physics>
    <gravity>0 0 -9.81</gravity>
    <gui fullscreen='0'>
      <camera name='user_camera'>
        <pose frame=''>-3.16877 1.79675 3.52022 0 0.557796 -0.259807</pose>
        <view_controller>orbit</view_controller>
        <projection_type>perspective</projection_type>
      </camera>
    </gui>
    <magnetic_field>6e-06 2.3e-05 -4.2e-05</magnetic_field>
    <atmosphere type='adiabatic'/>
    <scene>
      <ambient>0.4 0.4 0.4 1</ambient>
      <background>0.7 0.7 0.7 1</background>
      <shadows>1</shadows>
    </scene>
    <spherical_coordinates>
      <surface_model>EARTH_WGS84</surface_model>
      <latitude_deg>0</latitude_deg>
      <longitude_deg>0</longitude_deg>
      <elevation>0</elevation>
      <heading_deg>0</heading_deg>
    </spherical_coordinates>
    <model name='sawyer'>
      <link name='base'>
        <pose frame=''>0 0 0 0 -0 0</pose>
        <inertial>
          <pose frame=''>-0.000624 -2.8e-05 0.065404 0 -0 0</pose>
          <mass>2.0687</mass>
          <inertia>
            <ixx>0.0067599</ixx>
            <ixy>-4.2024e-05</ixy>
            <ixz>-6.1904e-07</ixz>
            <iyy>0.0067877</iyy>
            <iyz>1.5888e-05</iyz>
            <izz>0.0074031</izz>
          </inertia>
        </inertial>
        <collision name='base_fixed_joint_lump__right_arm_base_link_collision'>
          <pose frame=''>0 0 0.12 0 -0 0</pose>
          <geometry>
            <cylinder>
              <length>0.24</length>
              <radius>0.08</radius>
            </cylinder>
          </geometry>
          <max_contacts>10</max_contacts>
          <surface>
            <contact>
              <ode/>
            </contact>
            <bounce/>
            <friction>
              <torsional>
                <ode/>
              </torsional>
              <ode/>
            </friction>
          </surface>
        </collision>
        <visual name='base_fixed_joint_lump__right_arm_base_link_visual'>
          <pose frame=''>0 0 0 0 -0 0</pose>
          <geometry>
            <mesh>
              <scale>1 1 1</scale>
              <uri>/home/deep/RTL/catkin_ws/src/sawyer_robot/sawyer_description/meshes/sawyer_pv/base.DAE</uri>
            </mesh>
          </geometry>
        </visual>
        <visual name='base_fixed_joint_lump__torso_visual_1'>
          <pose frame=''>0 0 0 0 -0 0</pose>
          <geometry>
            <box>
              <size>0.001 0.001 0.001</size>
            </box>
          </geometry>
          <material>
            <script>
              <uri>__default__</uri>
              <name>__default__</name>
            </script>
          </material>
        </visual>
        <gravity>1</gravity>
        <velocity_decay/>
        <self_collide>0</self_collide>
        <self_collide>1</self_collide>
        <kinematic>0</kinematic>
      </link>
      <joint name='fixed' type='revolute'>
        <child>base</child>
        <parent>world</parent>
        <axis>
          <limit>
            <lower>0</lower>
            <upper>0</upper>
          </limit>
          <dynamics>
            <damping>0</damping>
            <friction>0</friction>
            <spring_reference>0</spring_reference>
            <spring_stiffness>0</spring_stiffness>
          </dynamics>
          <use_parent_model_frame>1</use_parent_model_frame>
          <xyz>0 0 1</xyz>
        </axis>
      </joint>
      <link name='right_l0'>
        <pose frame=''>0 0 0.08 0 -0 0</pose>
        <inertial>
          <pose frame=''>0.024366 0.010969 0.14363 0 -0 0</pose>
          <mass>5.3213</mass>
          <inertia>
            <ixx>0.053314</ixx>
            <ixy>0.0047093</ixy>
            <ixz>0.011734</ixz>
            <iyy>0.057902</iyy>
            <iyz>0.0080179</iyz>
            <izz>0.023659</izz>
          </inertia>
        </inertial>
        <collision name='right_l0_collision'>
          <pose frame=''>0.08 0 0.23 0 -0 0</pose>
          <geometry>
            <sphere>
              <radius>0.07</radius>
            </sphere>
          </geometry>
          <max_contacts>10</max_contacts>
          <surface>
            <contact>
              <ode/>
            </contact>
            <bounce/>
            <friction>
              <torsional>
                <ode/>
              </torsional>
              <ode/>
            </friction>
          </surface>
        </collision>
        <visual name='right_l0_visual'>
          <pose frame=''>0 0 0 0 -0 0</pose>
          <geometry>
            <mesh>
              <scale>1 1 1</scale>
              <uri>/home/deep/RTL/catkin_ws/src/sawyer_robot/sawyer_description/meshes/sawyer_mp3/l0.DAE</uri>
            </mesh>
          </geometry>
        </visual>
        <self_collide>0</self_collide>
        <kinematic>0</kinematic>
        <gravity>1</gravity>
      </link>
      <joint name='right_j0' type='revolute'>
        <child>right_l0</child>
        <parent>base</parent>
        <axis>
          <xyz>0 0 1</xyz>
          <limit>
            <lower>-3.0503</lower>
            <upper>3.0503</upper>
            <effort>80</effort>
            <velocity>1.74</velocity>
          </limit>
          <dynamics>
            <damping>10</damping>
            <friction>5</friction>
            <spring_reference>0</spring_reference>
            <spring_stiffness>0</spring_stiffness>
          </dynamics>
          <use_parent_model_frame>1</use_parent_model_frame>
        </axis>
        <physics>
          <provide_feedback>1</provide_feedback>
          <ode>
            <provide_feedback>1</provide_feedback>
            <implicit_spring_damper>1</implicit_spring_damper>
            <cfm_damping>1</cfm_damping>
            <limit>
              <cfm>0</cfm>
              <erp>0.2</erp>
            </limit>
          </ode>
        </physics>
      </joint>
      <link name='head'>
        <pose frame=''>0 0 0.3765 0 -0 0</pose>
        <inertial>
          <pose frame=''>0.005321 -2.7e-05 0.1021 0 -0 0</pose>
          <mass>1.5795</mass>
          <inertia>
            <ixx>0.011833</ixx>
            <ixy>-4.4669e-06</ixy>
            <ixz>4.9425e-05</ixz>
            <iyy>0.0082709</iyy>
            <iyz>4.2124e-07</iyz>
            <izz>0.0049661</izz>
          </inertia>
        </inertial>
        <collision name='head_collision'>
          <pose frame=''>0 0 0.08 0 -0 0</pose>
          <geometry>
            <sphere>
              <radius>0.18</radius>
            </sphere>
          </geometry>
          <max_contacts>10</max_contacts>
          <surface>
            <contact>
              <ode/>
            </contact>
            <bounce/>
            <friction>
              <torsional>
                <ode/>
              </torsional>
              <ode/>
            </friction>
          </surface>
        </collision>
        <collision name='head_fixed_joint_lump__screen_collision_1'>
          <pose frame=''>0.03 0 0.105 1.5708 -0 1.5708</pose>
          <geometry>
            <sphere>
              <radius>0.001</radius>
            </sphere>
          </geometry>
          <surface>
            <contact>
              <ode/>
            </contact>
            <friction>
              <ode/>
              <torsional>
                <ode/>
              </torsional>
            </friction>
            <bounce/>
          </surface>
          <max_contacts>10</max_contacts>
        </collision>
        <visual name='head_visual'>
          <pose frame=''>0 0 0 0 -0 0</pose>
          <geometry>
            <mesh>
              <scale>1 1 1</scale>
              <uri>/home/deep/RTL/catkin_ws/src/sawyer_robot/sawyer_description/meshes/sawyer_pv/head.DAE</uri>
            </mesh>
          </geometry>
        </visual>
        <visual name='head_fixed_joint_lump__screen_visual_1'>
          <pose frame=''>0.03 0 0.105 1.5708 -0 1.5708</pose>
          <geometry>
            <box>
              <size>0.24 0.14 0.002</size>
            </box>
          </geometry>
          <plugin name='screen_video_controller' filename='libgazebo_ros_video.so'>
            <height>600</height>
            <width>1024</width>
            <topicName>/robot/head_display</topicName>
            <robotNamespace>/robot</robotNamespace>
          </plugin>
          <material>
            <script>
              <uri>__default__</uri>
              <name>__default__</name>
            </script>
          </material>
        </visual>
        <velocity_decay/>
        <gravity>1</gravity>
        <velocity_decay/>
        <self_collide>0</self_collide>
        <sensor name='head_camera' type='camera'>
          <update_rate>10</update_rate>
          <camera name='head_camera'>
            <horizontal_fov>2.00787</horizontal_fov>
            <image>
              <width>1280</width>
              <height>800</height>
              <format>R8G8B8</format>
            </image>
            <clip>
              <near>0.1</near>
              <far>50</far>
            </clip>
          </camera>
          <plugin name='camera_controller' filename='libgazebo_ros_camera.so'>
            <alwaysOn>true</alwaysOn>
            <updateRate>10</updateRate>
            <cameraName>head_camera</cameraName>
            <imageTopicName>/io/internal_camera/head_camera/image_raw</imageTopicName>
            <cameraInfoTopicName>/io/internal_camera/head_camera/camera_info</cameraInfoTopicName>
            <frameName>head_camera</frameName>
            <focalLength>407.391526</focalLength>
            <robotNamespace>/</robotNamespace>
          </plugin>
          <pose frame=''>0.022803 0 0.216572 0 0.558504 0</pose>
        </sensor>
        <kinematic>0</kinematic>
      </link>
      <joint name='head_pan' type='revolute'>
        <child>head</child>
        <parent>right_l0</parent>
        <axis>
          <xyz>0 0 1</xyz>
          <limit>
            <lower>-5.0952</lower>
            <upper>0.9064</upper>
            <effort>8</effort>
            <velocity>1.8</velocity>
          </limit>
          <dynamics>
            <damping>1</damping>
            <friction>0.5</friction>
            <spring_reference>0</spring_reference>
            <spring_stiffness>0</spring_stiffness>
          </dynamics>
          <use_parent_model_frame>1</use_parent_model_frame>
        </axis>
        <physics>
          <provide_feedback>1</provide_feedback>
          <ode>
            <provide_feedback>1</provide_feedback>
            <implicit_spring_damper>1</implicit_spring_damper>
            <cfm_damping>1</cfm_damping>
            <limit>
              <cfm>0</cfm>
              <erp>0.2</erp>
            </limit>
          </ode>
        </physics>
      </joint>
      <link name='right_l1'>
        <pose frame=''>0.081 0.05 0.317 1.57078 1.57079 3.14158</pose>
        <inertial>
          <pose frame=''>-0.003085 -0.026811 0.092521 0 -0 0</pose>
          <mass>4.505</mass>
          <inertia>
            <ixx>0.022398</ixx>
            <ixy>-0.00023986</ixy>
            <ixz>-0.00029362</ixz>
            <iyy>0.014613</iyy>
            <iyz>-0.0060875</iyz>
            <izz>0.017295</izz>
          </inertia>
        </inertial>
        <collision name='right_l1_collision'>
          <pose frame=''>0 0 0.1225 0 -0 0</pose>
          <geometry>
            <sphere>
              <radius>0.07</radius>
            </sphere>
          </geometry>
          <max_contacts>10</max_contacts>
          <surface>
            <contact>
              <ode/>
            </contact>
            <bounce/>
            <friction>
              <torsional>
                <ode/>
              </torsional>
              <ode/>
            </friction>
          </surface>
        </collision>
        <collision name='right_l1_2_collision_1'>
          <pose frame=''>0 0 0.035 0 -0 0</pose>
          <geometry>
            <cylinder>
              <length>0.14</length>
              <radius>0.07</radius>
            </cylinder>
          </geometry>
          <max_contacts>10</max_contacts>
          <surface>
            <contact>
              <ode/>
            </contact>
            <bounce/>
            <friction>
              <torsional>
                <ode/>
              </torsional>
              <ode/>
            </friction>
          </surface>
        </collision>
        <visual name='right_l1_visual'>
          <pose frame=''>0 0 0 0 -0 0</pose>
          <geometry>
            <mesh>
              <scale>1 1 1</scale>
              <uri>/home/deep/RTL/catkin_ws/src/sawyer_robot/sawyer_description/meshes/sawyer_mp3/l1.DAE</uri>
            </mesh>
          </geometry>
        </visual>
        <self_collide>0</self_collide>
        <kinematic>0</kinematic>
        <gravity>1</gravity>
      </link>
      <joint name='right_j1' type='revolute'>
        <child>right_l1</child>
        <parent>right_l0</parent>
        <axis>
          <xyz>0 1 0</xyz>
          <limit>
            <lower>-3.8095</lower>
            <upper>2.2736</upper>
            <effort>80</effort>
            <velocity>1.328</velocity>
          </limit>
          <dynamics>
            <damping>5</damping>
            <friction>2</friction>
            <spring_reference>0</spring_reference>
            <spring_stiffness>0</spring_stiffness>
          </dynamics>
          <use_parent_model_frame>1</use_parent_model_frame>
        </axis>
        <physics>
          <provide_feedback>1</provide_feedback>
          <ode>
            <provide_feedback>1</provide_feedback>
            <implicit_spring_damper>1</implicit_spring_damper>
            <cfm_damping>1</cfm_damping>
            <limit>
              <cfm>0</cfm>
              <erp>0.2</erp>
            </limit>
          </ode>
        </physics>
      </joint>
      <link name='right_l2'>
        <pose frame=''>0.221 0.1925 0.317 3.14158 1.57079 3.14158</pose>
        <inertial>
          <pose frame=''>-0.00016 -0.014967 0.13582 0 -0 0</pose>
          <mass>1.745</mass>
          <inertia>
            <ixx>0.025506</ixx>
            <ixy>4.4101e-06</ixy>
            <ixz>1.4955e-05</ixz>
            <iyy>0.0253</iyy>
            <iyz>-0.0033204</iyz>
            <izz>0.0034179</izz>
          </inertia>
        </inertial>
        <collision name='right_l2_collision'>
          <pose frame=''>0 0 0.08 0 -0 0</pose>
          <geometry>
            <cylinder>
              <length>0.34</length>
              <radius>0.06</radius>
            </cylinder>
          </geometry>
          <max_contacts>10</max_contacts>
          <surface>
            <contact>
              <ode/>
            </contact>
            <bounce/>
            <friction>
              <torsional>
                <ode/>
              </torsional>
              <ode/>
            </friction>
          </surface>
        </collision>
        <collision name='right_l2_2_collision_1'>
          <pose frame=''>0 0 0.26 0 -0 0</pose>
          <geometry>
            <sphere>
              <radius>0.06</radius>
            </sphere>
          </geometry>
          <max_contacts>10</max_contacts>
          <surface>
            <contact>
              <ode/>
            </contact>
            <bounce/>
            <friction>
              <torsional>
                <ode/>
              </torsional>
              <ode/>
            </friction>
          </surface>
        </collision>
        <visual name='right_l2_visual'>
          <pose frame=''>0 0 0 0 -0 0</pose>
          <geometry>
            <mesh>
              <scale>1 1 1</scale>
              <uri>/home/deep/RTL/catkin_ws/src/sawyer_robot/sawyer_description/meshes/sawyer_pv/l2.DAE</uri>
            </mesh>
          </geometry>
        </visual>
        <self_collide>0</self_collide>
        <kinematic>0</kinematic>
        <gravity>1</gravity>
      </link>
      <joint name='right_j2' type='revolute'>
        <child>right_l2</child>
        <parent>right_l1</parent>
        <axis>
          <xyz>1 0 0</xyz>
          <limit>
            <lower>-3.0426</lower>
            <upper>3.0426</upper>
            <effort>40</effort>
            <velocity>1.957</velocity>
          </limit>
          <dynamics>
            <damping>5</damping>
            <friction>2</friction>
            <spring_reference>0</spring_reference>
            <spring_stiffness>0</spring_stiffness>
          </dynamics>
          <use_parent_model_frame>1</use_parent_model_frame>
        </axis>
        <physics>
          <provide_feedback>1</provide_feedback>
          <ode>
            <provide_feedback>1</provide_feedback>
            <implicit_spring_damper>1</implicit_spring_damper>
            <cfm_damping>1</cfm_damping>
            <limit>
              <cfm>0</cfm>
              <erp>0.2</erp>
            </limit>
          </ode>
        </physics>
      </joint>
      <link name='right_l3'>
        <pose frame=''>0.481 0.1505 0.317 1.57078 1.57079 3.14158</pose>
        <inertial>
          <pose frame=''>-0.004814 -0.0281 -0.084154 0 -0 0</pose>
          <mass>2.5097</mass>
          <inertia>
            <ixx>0.01016</ixx>
            <ixy>-9.7452e-06</ixy>
            <ixz>0.00026624</ixz>
            <iyy>0.0065685</iyy>
            <iyz>0.0030316</iyz>
            <izz>0.0069078</izz>
          </inertia>
        </inertial>
        <collision name='right_l3_collision'>
          <pose frame=''>0 -0.01 -0.12 0 -0 0</pose>
          <geometry>
            <sphere>
              <radius>0.06</radius>
            </sphere>
          </geometry>
          <max_contacts>10</max_contacts>
          <surface>
            <contact>
              <ode/>
            </contact>
            <bounce/>
            <friction>
              <torsional>
                <ode/>
              </torsional>
              <ode/>
            </friction>
          </surface>
        </collision>
        <visual name='right_l3_visual'>
          <pose frame=''>0 0 0 0 -0 0</pose>
          <geometry>
            <mesh>
              <scale>1 1 1</scale>
              <uri>/home/deep/RTL/catkin_ws/src/sawyer_robot/sawyer_description/meshes/sawyer_pv/l3.DAE</uri>
            </mesh>
          </geometry>
        </visual>
        <self_collide>0</self_collide>
        <kinematic>0</kinematic>
        <gravity>1</gravity>
      </link>
      <joint name='right_j3' type='revolute'>
        <child>right_l3</child>
        <parent>right_l2</parent>
        <axis>
          <xyz>0 1 0</xyz>
          <limit>
            <lower>-3.0439</lower>
            <upper>3.0439</upper>
            <effort>40</effort>
            <velocity>1.957</velocity>
          </limit>
          <dynamics>
            <damping>1</damping>
            <friction>0.5</friction>
            <spring_reference>0</spring_reference>
            <spring_stiffness>0</spring_stiffness>
          </dynamics>
          <use_parent_model_frame>1</use_parent_model_frame>
        </axis>
        <physics>
          <provide_feedback>1</provide_feedback>
          <ode>
            <provide_feedback>1</provide_feedback>
            <implicit_spring_damper>1</implicit_spring_damper>
            <cfm_damping>1</cfm_damping>
            <limit>
              <cfm>0</cfm>
              <erp>0.2</erp>
            </limit>
          </ode>
        </physics>
      </joint>
      <link name='right_l4'>
        <pose frame=''>0.606 0.024 0.317 3.14158 1.57079 3.14158</pose>
        <inertial>
          <pose frame=''>-0.001884 0.0069 0.1341 0 -0 0</pose>
          <mass>1.1136</mass>
          <inertia>
            <ixx>0.013557</ixx>
            <ixy>1.8109e-05</ixy>
            <ixz>0.00013523</ixz>
            <iyy>0.013555</iyy>
            <iyz>0.0010561</iyz>
            <izz>0.0013658</izz>
          </inertia>
        </inertial>
        <collision name='right_l4_collision'>
          <pose frame=''>0 0 0.11 0 -0 0</pose>
          <geometry>
            <cylinder>
              <length>0.3</length>
              <radius>0.045</radius>
            </cylinder>
          </geometry>
          <max_contacts>10</max_contacts>
          <surface>
            <contact>
              <ode/>
            </contact>
            <bounce/>
            <friction>
              <torsional>
                <ode/>
              </torsional>
              <ode/>
            </friction>
          </surface>
        </collision>
        <collision name='right_l4_2_collision_1'>
          <pose frame=''>0 0.01 0.26 0 -0 0</pose>
          <geometry>
            <sphere>
              <radius>0.06</radius>
            </sphere>
          </geometry>
          <max_contacts>10</max_contacts>
          <surface>
            <contact>
              <ode/>
            </contact>
            <bounce/>
            <friction>
              <torsional>
                <ode/>
              </torsional>
              <ode/>
            </friction>
          </surface>
        </collision>
        <visual name='right_l4_visual'>
          <pose frame=''>0 0 0 0 -0 0</pose>
          <geometry>
            <mesh>
              <scale>1 1 1</scale>
              <uri>/home/deep/RTL/catkin_ws/src/sawyer_robot/sawyer_description/meshes/sawyer_pv/l4.DAE</uri>
            </mesh>
          </geometry>
        </visual>
        <self_collide>0</self_collide>
        <kinematic>0</kinematic>
        <gravity>1</gravity>
      </link>
      <joint name='right_j4' type='revolute'>
        <child>right_l4</child>
        <parent>right_l3</parent>
        <axis>
          <xyz>1 0 0</xyz>
          <limit>
            <lower>-2.9761</lower>
            <upper>2.9761</upper>
            <effort>9</effort>
            <velocity>3.485</velocity>
          </limit>
          <dynamics>
            <damping>2</damping>
            <friction>1</friction>
            <spring_reference>0</spring_reference>
            <spring_stiffness>0</spring_stiffness>
          </dynamics>
          <use_parent_model_frame>1</use_parent_model_frame>
        </axis>
        <physics>
          <provide_feedback>1</provide_feedback>
          <ode>
            <provide_feedback>1</provide_feedback>
            <implicit_spring_damper>1</implicit_spring_damper>
            <cfm_damping>1</cfm_damping>
            <limit>
              <cfm>0</cfm>
              <erp>0.2</erp>
            </limit>
          </ode>
        </physics>
      </joint>
      <link name='right_l5'>
        <pose frame=''>0.881 0.055 0.317 1.57078 1.57079 3.14158</pose>
        <inertial>
          <pose frame=''>0.006113 -0.023697 0.076416 0 -0 0</pose>
          <mass>1.5625</mass>
          <inertia>
            <ixx>0.0047328</ixx>
            <ixy>0.00011526</ixy>
            <ixz>4.6269e-05</ixz>
            <iyy>0.0029676</iyy>
            <iyz>-0.0011557</iyz>
            <izz>0.0031762</izz>
          </inertia>
        </inertial>
        <collision name='right_l5_collision'>
          <pose frame=''>0 0 0.1 0 -0 0</pose>
          <geometry>
            <sphere>
              <radius>0.06</radius>
            </sphere>
          </geometry>
          <max_contacts>10</max_contacts>
          <surface>
            <contact>
              <ode/>
            </contact>
            <bounce/>
            <friction>
              <torsional>
                <ode/>
              </torsional>
              <ode/>
            </friction>
          </surface>
        </collision>
        <visual name='right_l5_visual'>
          <pose frame=''>0 0 0 0 -0 0</pose>
          <geometry>
            <mesh>
              <scale>1 1 1</scale>
              <uri>/home/deep/RTL/catkin_ws/src/sawyer_robot/sawyer_description/meshes/sawyer_pv/l5.DAE</uri>
            </mesh>
          </geometry>
        </visual>
        <gravity>1</gravity>
        <velocity_decay/>
        <self_collide>0</self_collide>
        <sensor name='right_hand_camera' type='camera'>
          <update_rate>10</update_rate>
          <camera name='right_hand_camera'>
            <horizontal_fov>1.09929</horizontal_fov>
            <image>
              <width>752</width>
              <height>480</height>
              <format>L8</format>
            </image>
            <clip>
              <near>0.02</near>
              <far>10</far>
            </clip>
          </camera>
          <plugin name='camera_controller' filename='libgazebo_ros_camera.so'>
            <alwaysOn>true</alwaysOn>
            <updateRate>10.0</updateRate>
            <cameraName>right_hand_camera</cameraName>
            <imageTopicName>/io/internal_camera/right_hand_camera/image_raw</imageTopicName>
            <cameraInfoTopicName>/io/internal_camera/right_hand_camera/camera_info</cameraInfoTopicName>
            <frameName>right_hand_camera</frameName>
            <focalLength>613.760435</focalLength>
            <robotNamespace>/</robotNamespace>
          </plugin>
          <pose frame=''>0.039552 -0.033 0.0695 1.5708 -0 0</pose>
        </sensor>
        <kinematic>0</kinematic>
      </link>
      <joint name='right_j5' type='revolute'>
        <child>right_l5</child>
        <parent>right_l4</parent>
        <axis>
          <xyz>0 1 0</xyz>
          <limit>
            <lower>-2.9761</lower>
            <upper>2.9761</upper>
            <effort>9</effort>
            <velocity>3.485</velocity>
          </limit>
          <dynamics>
            <damping>1</damping>
            <friction>0.5</friction>
            <spring_reference>0</spring_reference>
            <spring_stiffness>0</spring_stiffness>
          </dynamics>
          <use_parent_model_frame>1</use_parent_model_frame>
        </axis>
        <physics>
          <provide_feedback>1</provide_feedback>
          <ode>
            <provide_feedback>1</provide_feedback>
            <implicit_spring_damper>1</implicit_spring_damper>
            <cfm_damping>1</cfm_damping>
            <limit>
              <cfm>0</cfm>
              <erp>0.2</erp>
            </limit>
          </ode>
        </physics>
      </joint>
      <link name='right_l6'>
        <pose frame=''>0.991 0.1603 0.317 1.57084 -1.39627 1.57075</pose>
        <inertial>
          <pose frame=''>0.053529 -0.007799 0.076583 0 -0 0</pose>
          <mass>0.9032</mass>
          <inertia>
            <ixx>0.0178758</ixx>
            <ixy>-0.00951194</ixy>
            <ixz>-0.012447</ixz>
            <iyy>0.0160881</iyy>
            <iyz>0.0107008</iyz>
            <izz>0.0162132</izz>
          </inertia>
        </inertial>
        <collision name='right_l6_collision'>
          <pose frame=''>0 0.015 -0.01 0 -0 0</pose>
          <geometry>
            <cylinder>
              <length>0.05</length>
              <radius>0.055</radius>
            </cylinder>
          </geometry>
          <max_contacts>10</max_contacts>
          <surface>
            <contact>
              <ode/>
            </contact>
            <bounce/>
            <friction>
              <torsional>
                <ode/>
              </torsional>
              <ode/>
            </friction>
          </surface>
        </collision>
        <collision name='right_l6_fixed_joint_lump__right_hand_collision_1'>
          <pose frame=''>0 0 0.0445 0 -0 1.5708</pose>
          <geometry>
            <cylinder>
              <length>0.03</length>
              <radius>0.035</radius>
            </cylinder>
          </geometry>
          <max_contacts>10</max_contacts>
          <surface>
            <contact>
              <ode/>
            </contact>
            <bounce/>
            <friction>
              <torsional>
                <ode/>
              </torsional>
              <ode/>
            </friction>
          </surface>
        </collision>
        <collision name='right_l6_fixed_joint_lump__camera_link_collision_2'>
          <pose frame=''>0.0875 -0 0.1251 3.14159 -1.57079 -3e-06</pose>
          <geometry>
            <box>
              <size>0.02505 0.09 0.025</size>
            </box>
          </geometry>
          <surface>
            <contact>
              <ode/>
            </contact>
            <friction>
              <ode/>
              <torsional>
                <ode/>
              </torsional>
            </friction>
            <bounce/>
          </surface>
          <max_contacts>10</max_contacts>
        </collision>
        <visual name='right_l6_visual'>
          <pose frame=''>0 0 0 0 -0 0</pose>
          <geometry>
            <mesh>
              <scale>1 1 1</scale>
              <uri>/home/deep/RTL/catkin_ws/src/sawyer_robot/sawyer_description/meshes/sawyer_mp1/l6.DAE</uri>
            </mesh>
          </geometry>
        </visual>
        <visual name='right_l6_fixed_joint_lump__camera_link_visual_1'>
          <pose frame=''>0.0875 -0 0.1294 0 -0 -1.5708</pose>
          <geometry>
            <mesh>
              <scale>1 1 1</scale>
              <uri>/home/deep/RTL/catkin_ws/src/realsense-ros/realsense2_description/meshes/d435.dae</uri>
            </mesh>
          </geometry>
          <material>
            <script>
              <uri>__default__</uri>
              <name>__default__</name>
            </script>
          </material>
        </visual>
        <gravity>1</gravity>
        <velocity_decay/>
        <self_collide>0</self_collide>
        <sensor name='camera' type='depth'>
          <update_rate>30</update_rate>
          <camera name='camera'>
            <horizontal_fov>1.21126</horizontal_fov>
            <image>
              <width>1920</width>
              <height>1080</height>
              <format>R8G8B8</format>
            </image>
            <clip>
              <near>0.02</near>
              <far>1000</far>
            </clip>
            <noise>
              <type>gaussian</type>
              <mean>0</mean>
              <stddev>0.02</stddev>
            </noise>
          </camera>
          <plugin name='camera_plugin' filename='libgazebo_ros_openni_kinect.so'>
            <baseline>0.05</baseline>
            <alwaysOn>true</alwaysOn>
            <updateRate>0.0</updateRate>
            <cameraName>/camera</cameraName>
            <imageTopicName>color/image_raw</imageTopicName>
            <cameraInfoTopicName>color/camera_info</cameraInfoTopicName>
            <depthImageTopicName>aligned_depth_to_color/image_raw</depthImageTopicName>
            <depthImageCameraInfoTopicName>aligned_depth_to_color/camera_info</depthImageCameraInfoTopicName>
            <pointCloudTopicName>depth/points</pointCloudTopicName>
            <frameName>camera_depth_optical_frame</frameName>
            <pointCloudCutoff>0.1</pointCloudCutoff>
            <pointCloudCutoffMax>8.0</pointCloudCutoffMax>
            <distortionK1>0</distortionK1>
            <distortionK2>0</distortionK2>
            <distortionK3>0</distortionK3>
            <distortionT1>0</distortionT1>
            <distortionT2>0</distortionT2>
            <CxPrime>0</CxPrime>
            <Cx>0</Cx>
            <Cy>0</Cy>
            <focalLength>0</focalLength>
            <hackBaseline>0.05</hackBaseline>
            <robotNamespace>/</robotNamespace>
          </plugin>
          <pose frame=''>0.0875 -0.0175 0.1251 3.14159 -1.57079 -3e-06</pose>
        </sensor>
        <kinematic>0</kinematic>
      </link>
      <joint name='right_j6' type='revolute'>
        <child>right_l6</child>
        <parent>right_l5</parent>
        <axis>
          <xyz>1 0 -7e-06</xyz>
          <limit>
            <lower>-3.14</lower>
            <upper>3.14</upper>
            <effort>9</effort>
            <velocity>4.545</velocity>
          </limit>
          <dynamics>
            <damping>1</damping>
            <friction>0.5</friction>
            <spring_reference>0</spring_reference>
            <spring_stiffness>0</spring_stiffness>
          </dynamics>
          <use_parent_model_frame>1</use_parent_model_frame>
        </axis>
        <physics>
          <provide_feedback>1</provide_feedback>
          <ode>
            <provide_feedback>1</provide_feedback>
            <implicit_spring_damper>1</implicit_spring_damper>
            <cfm_damping>1</cfm_damping>
            <limit>
              <cfm>0</cfm>
              <erp>0.2</erp>
            </limit>
          </ode>
        </physics>
      </joint>
      <static>0</static>
      <plugin name='sawyer_ros_control' filename='libsawyer_gazebo_ros_control.so'>
        <robotNamespace>/robot</robotNamespace>
        <robotSimType>sawyer_gazebo/SawyerRobotHWSim</robotSimType>
        <controlPeriod>0.001</controlPeriod>
        <eStopTopic>sim_estop</eStopTopic>
      </plugin>
      <pose frame=''>0 0 0.93 0 -0 0</pose>
    </model>
    <model name='cafe_table'>
      <static>1</static>
      <link name='link'>
        <collision name='surface'>
          <pose frame=''>0 0 0.755 0 -0 0</pose>
          <geometry>
            <box>
              <size>0.913 0.913 0.04</size>
            </box>
          </geometry>
          <max_contacts>10</max_contacts>
          <surface>
            <contact>
              <ode/>
            </contact>
            <bounce/>
            <friction>
              <torsional>
                <ode/>
              </torsional>
              <ode/>
            </friction>
          </surface>
        </collision>
        <collision name='column'>
          <pose frame=''>0 0 0.37 0 -0 0</pose>
          <geometry>
            <box>
              <size>0.042 0.042 0.74</size>
            </box>
          </geometry>
          <max_contacts>10</max_contacts>
          <surface>
            <contact>
              <ode/>
            </contact>
            <bounce/>
            <friction>
              <torsional>
                <ode/>
              </torsional>
              <ode/>
            </friction>
          </surface>
        </collision>
        <collision name='base'>
          <pose frame=''>0 0 0.02 0 -0 0</pose>
          <geometry>
            <box>
              <size>0.56 0.56 0.04</size>
            </box>
          </geometry>
          <max_contacts>10</max_contacts>
          <surface>
            <contact>
              <ode/>
            </contact>
            <bounce/>
            <friction>
              <torsional>
                <ode/>
              </torsional>
              <ode/>
            </friction>
          </surface>
        </collision>
        <visual name='visual'>
          <geometry>
            <mesh>
              <uri>model://cafe_table/meshes/cafe_table.dae</uri>
              <scale>1 1 1</scale>
            </mesh>
          </geometry>
        </visual>
        <self_collide>0</self_collide>
        <kinematic>0</kinematic>
        <gravity>1</gravity>
      </link>
      <pose frame=''>-0.015887 1.03588 0 0 -0 0</pose>
    </model>
    <model name='beer'>
      <link name='link'>
        <pose frame=''>0 0 0.115 0 -0 0</pose>
        <inertial>
          <mass>0.39</mass>
          <inertia>
            <ixx>0.00058</ixx>
            <ixy>0</ixy>
            <ixz>0</ixz>
            <iyy>0.00058</iyy>
            <iyz>0</iyz>
            <izz>0.00019</izz>
          </inertia>
        </inertial>
        <collision name='collision'>
          <geometry>
            <cylinder>
              <radius>0.055</radius>
              <length>0.23</length>
            </cylinder>
          </geometry>
          <max_contacts>10</max_contacts>
          <surface>
            <contact>
              <ode/>
            </contact>
            <bounce/>
            <friction>
              <torsional>
                <ode/>
              </torsional>
              <ode/>
            </friction>
          </surface>
        </collision>
        <visual name='visual'>
          <geometry>
            <cylinder>
              <radius>0.055</radius>
              <length>0.23</length>
            </cylinder>
          </geometry>
          <material>
            <script>
              <uri>model://beer/materials/scripts</uri>
              <uri>model://beer/materials/textures</uri>
              <name>Beer/Diffuse</name>
            </script>
          </material>
        </visual>
        <self_collide>0</self_collide>
        <kinematic>0</kinematic>
        <gravity>1</gravity>
      </link>
      <pose frame=''>0.598961 0.752584 0 0 -0 0</pose>
    </model>
    <model name='cricket_ball'>
      <link name='link'>
        <pose frame=''>0 0 0.0375 0 -0 0</pose>
        <inertial>
          <mass>0.1467</mass>
          <inertia>
            <ixx>8.25187e-05</ixx>
            <ixy>0</ixy>
            <ixz>0</ixz>
            <iyy>8.25187e-05</iyy>
            <iyz>0</iyz>
            <izz>8.25187e-05</izz>
          </inertia>
        </inertial>
        <collision name='collision'>
          <geometry>
            <sphere>
              <radius>0.0375</radius>
            </sphere>
          </geometry>
          <surface>
            <contact>
              <poissons_ratio>0.347</poissons_ratio>
              <elastic_modulus>8.8e+09</elastic_modulus>
              <ode>
                <kp>100000</kp>
                <kd>100</kd>
                <max_vel>100</max_vel>
                <min_depth>0.001</min_depth>
              </ode>
            </contact>
            <friction>
              <torsional>
                <coefficient>1</coefficient>
                <use_patch_radius>0</use_patch_radius>
                <surface_radius>0.01</surface_radius>
                <ode/>
              </torsional>
              <ode/>
            </friction>
            <bounce/>
          </surface>
          <max_contacts>10</max_contacts>
        </collision>
        <visual name='visual'>
          <geometry>
            <sphere>
              <radius>0.0375</radius>
            </sphere>
          </geometry>
          <material>
            <script>
              <uri>file://media/materials/scripts/gazebo.material</uri>
              <name>Gazebo/Red</name>
            </script>
          </material>
        </visual>
        <velocity_decay>
          <linear>0</linear>
          <angular>0.005</angular>
        </velocity_decay>
        <self_collide>0</self_collide>
        <kinematic>0</kinematic>
        <gravity>1</gravity>
      </link>
      <pose frame=''>0.770033 0.537296 0 0 -0 0</pose>
    </model>
    <model name='hammer'>
      <static>1</static>
      <link name='link'>
        <collision name='collision'>
          <geometry>
            <mesh>
              <uri>model://hammer/meshes/hammer.dae</uri>
              <scale>1 1 1</scale>
            </mesh>
          </geometry>
          <max_contacts>10</max_contacts>
          <surface>
            <contact>
              <ode/>
            </contact>
            <bounce/>
            <friction>
              <torsional>
                <ode/>
              </torsional>
              <ode/>
            </friction>
          </surface>
        </collision>
        <visual name='visual'>
          <geometry>
            <mesh>
              <uri>model://hammer/meshes/hammer.dae</uri>
              <scale>1 1 1</scale>
            </mesh>
          </geometry>
        </visual>
        <self_collide>0</self_collide>
        <kinematic>0</kinematic>
        <gravity>1</gravity>
      </link>
      <pose frame=''>0.571952 0.390288 0 0 -0 0</pose>
    </model>
    <model name='bookshelf'>
      <static>1</static>
      <link name='link'>
        <inertial>
          <mass>1</mass>
        </inertial>
        <collision name='back'>
          <pose frame=''>0 0.005 0.6 0 -0 0</pose>
          <geometry>
            <box>
              <size>0.9 0.01 1.2</size>
            </box>
          </geometry>
          <max_contacts>10</max_contacts>
          <surface>
            <contact>
              <ode/>
            </contact>
            <bounce/>
            <friction>
              <torsional>
                <ode/>
              </torsional>
              <ode/>
            </friction>
          </surface>
        </collision>
        <visual name='visual1'>
          <pose frame=''>0 0.005 0.6 0 -0 0</pose>
          <geometry>
            <box>
              <size>0.9 0.01 1.2</size>
            </box>
          </geometry>
          <material>
            <script>
              <uri>file://media/materials/scripts/gazebo.material</uri>
              <name>Gazebo/Wood</name>
            </script>
          </material>
        </visual>
        <collision name='left_side'>
          <pose frame=''>0.45 -0.195 0.6 0 -0 0</pose>
          <geometry>
            <box>
              <size>0.02 0.4 1.2</size>
            </box>
          </geometry>
          <max_contacts>10</max_contacts>
          <surface>
            <contact>
              <ode/>
            </contact>
            <bounce/>
            <friction>
              <torsional>
                <ode/>
              </torsional>
              <ode/>
            </friction>
          </surface>
        </collision>
        <visual name='visual2'>
          <pose frame=''>0.45 -0.195 0.6 0 -0 0</pose>
          <geometry>
            <box>
              <size>0.02 0.4 1.2</size>
            </box>
          </geometry>
          <material>
            <script>
              <uri>file://media/materials/scripts/gazebo.material</uri>
              <name>Gazebo/Wood</name>
            </script>
          </material>
        </visual>
        <collision name='right_side'>
          <pose frame=''>-0.45 -0.195 0.6 0 -0 0</pose>
          <geometry>
            <box>
              <size>0.02 0.4 1.2</size>
            </box>
          </geometry>
          <max_contacts>10</max_contacts>
          <surface>
            <contact>
              <ode/>
            </contact>
            <bounce/>
            <friction>
              <torsional>
                <ode/>
              </torsional>
              <ode/>
            </friction>
          </surface>
        </collision>
        <visual name='visual3'>
          <pose frame=''>-0.45 -0.195 0.6 0 -0 0</pose>
          <geometry>
            <box>
              <size>0.02 0.4 1.2</size>
            </box>
          </geometry>
          <material>
            <script>
              <uri>file://media/materials/scripts/gazebo.material</uri>
              <name>Gazebo/Wood</name>
            </script>
          </material>
        </visual>
        <collision name='bottom'>
          <pose frame=''>0 -0.195 0.03 0 -0 0</pose>
          <geometry>
            <box>
              <size>0.88 0.4 0.06</size>
            </box>
          </geometry>
          <max_contacts>10</max_contacts>
          <surface>
            <contact>
              <ode/>
            </contact>
            <bounce/>
            <friction>
              <torsional>
                <ode/>
              </torsional>
              <ode/>
            </friction>
          </surface>
        </collision>
        <visual name='visual4'>
          <pose frame=''>0 -0.195 0.03 0 -0 0</pose>
          <geometry>
            <box>
              <size>0.88 0.4 0.06</size>
            </box>
          </geometry>
          <material>
            <script>
              <uri>file://media/materials/scripts/gazebo.material</uri>
              <name>Gazebo/Wood</name>
            </script>
          </material>
        </visual>
        <collision name='top'>
          <pose frame=''>0 -0.195 1.19 0 -0 0</pose>
          <geometry>
            <box>
              <size>0.88 0.4 0.02</size>
            </box>
          </geometry>
          <max_contacts>10</max_contacts>
          <surface>
            <contact>
              <ode/>
            </contact>
            <bounce/>
            <friction>
              <torsional>
                <ode/>
              </torsional>
              <ode/>
            </friction>
          </surface>
        </collision>
        <visual name='visual5'>
          <pose frame=''>0 -0.195 1.19 0 -0 0</pose>
          <geometry>
            <box>
              <size>0.88 0.4 0.02</size>
            </box>
          </geometry>
          <material>
            <script>
              <uri>file://media/materials/scripts/gazebo.material</uri>
              <name>Gazebo/Wood</name>
            </script>
          </material>
        </visual>
        <collision name='low_shelf'>
          <pose frame=''>0 -0.195 0.43 0 -0 0</pose>
          <geometry>
            <box>
              <size>0.88 0.4 0.02</size>
            </box>
          </geometry>
          <max_contacts>10</max_contacts>
          <surface>
            <contact>
              <ode/>
            </contact>
            <bounce/>
            <friction>
              <torsional>
                <ode/>
              </torsional>
              <ode/>
            </friction>
          </surface>
        </collision>
        <visual name='visual6'>
          <pose frame=''>0 -0.195 0.43 0 -0 0</pose>
          <geometry>
            <box>
              <size>0.88 0.4 0.02</size>
            </box>
          </geometry>
          <material>
            <script>
              <uri>file://media/materials/scripts/gazebo.material</uri>
              <name>Gazebo/Wood</name>
            </script>
          </material>
        </visual>
        <collision name='high_shelf'>
          <pose frame=''>0 -0.195 0.8 0 -0 0</pose>
          <geometry>
            <box>
              <size>0.88 0.4 0.02</size>
            </box>
          </geometry>
          <max_contacts>10</max_contacts>
          <surface>
            <contact>
              <ode/>
            </contact>
            <bounce/>
            <friction>
              <torsional>
                <ode/>
              </torsional>
              <ode/>
            </friction>
          </surface>
        </collision>
        <visual name='visual7'>
          <pose frame=''>0 -0.195 0.8 0 -0 0</pose>
          <geometry>
            <box>
              <size>0.88 0.4 0.02</size>
            </box>
          </geometry>
          <material>
            <script>
              <uri>file://media/materials/scripts/gazebo.material</uri>
              <name>Gazebo/Wood</name>
            </script>
          </material>
        </visual>
        <self_collide>0</self_collide>
        <kinematic>0</kinematic>
        <gravity>1</gravity>
      </link>
      <pose frame=''>0.085816 -0.551602 0 0 -0 0</pose>
    </model>
    <model name='coke_can_0'>
      <link name='link'>
        <inertial>
          <mass>0.39</mass>
          <inertia>
            <ixx>0.00055575</ixx>
            <ixy>0</ixy>
            <ixz>0</ixz>
            <iyy>0.00055575</iyy>
            <iyz>0</iyz>
            <izz>0.0001755</izz>
          </inertia>
        </inertial>
        <collision name='collision'>
          <pose frame=''>0.003937 0.004724 -0.18 0 -0 0</pose>
          <geometry>
            <mesh>
              <uri>model://coke_can/meshes/coke_can.dae</uri>
              <scale>1 1 1</scale>
            </mesh>
          </geometry>
          <max_contacts>10</max_contacts>
          <surface>
            <contact>
              <ode/>
            </contact>
            <bounce/>
            <friction>
              <torsional>
                <ode/>
              </torsional>
              <ode/>
            </friction>
          </surface>
        </collision>
        <visual name='visual'>
          <pose frame=''>0.003937 0.004724 -0.18 0 -0 0</pose>
          <geometry>
            <mesh>
              <uri>model://coke_can/meshes/coke_can.dae</uri>
              <scale>1 1 1</scale>
            </mesh>
          </geometry>
        </visual>
        <self_collide>0</self_collide>
        <kinematic>0</kinematic>
        <gravity>1</gravity>
      </link>
      <pose frame=''>1.20749 1.20863 0 0 -0 0</pose>
    </model>
    <state world_name='default'>
      <sim_time>1025 74000000</sim_time>
      <real_time>667 22772781</real_time>
      <wall_time>1591688016 837931198</wall_time>
      <iterations>628792</iterations>
      <model name='beer'>
        <pose frame=''>0.015291 1.05351 0.774992 1e-06 -2.7e-05 0.00041</pose>
        <scale>1 1 1</scale>
        <link name='link'>
          <pose frame=''>0.015288 1.05351 0.889992 1e-06 -2.7e-05 0.00041</pose>
          <velocity>0 0 0 0 -0 0</velocity>
          <acceleration>0 0 -9.81 0 -0 0</acceleration>
          <wrench>0 0 -3.8259 0 -0 0</wrench>
        </link>
      </model>
      <model name='bookshelf'>
        <pose frame=''>0.535504 -1.26579 0 0 0 -2.74905</pose>
        <scale>1 1 1</scale>
        <link name='link'>
          <pose frame=''>0.535504 -1.26579 0 0 0 -2.74905</pose>
          <velocity>0 0 0 0 -0 0</velocity>
          <acceleration>0 0 0 0 -0 0</acceleration>
          <wrench>0 0 0 0 -0 0</wrench>
        </link>
      </model>
      <model name='cafe_table'>
        <pose frame=''>0.047858 1.11074 0 0 -0 0</pose>
        <scale>1 1 1</scale>
        <link name='link'>
          <pose frame=''>0.047858 1.11074 0 0 -0 0</pose>
          <velocity>0 0 0 0 -0 0</velocity>
          <acceleration>0 0 0 0 -0 0</acceleration>
          <wrench>0 0 0 0 -0 0</wrench>
        </link>
      </model>
      <model name='coke_can_0'>
        <pose frame=''>-0.124483 0.872441 0.772428 -0.011215 0.004016 0.001184</pose>
        <scale>1 1 1</scale>
        <link name='link'>
          <pose frame=''>-0.124483 0.872441 0.772428 -0.011215 0.004016 0.001184</pose>
          <velocity>0 0 0 0 -0 0</velocity>
          <acceleration>0 0 -9.81 1e-06 -0 0</acceleration>
          <wrench>0 0 -3.8259 0 -0 0</wrench>
        </link>
      </model>
      <model name='cricket_ball'>
        <pose frame=''>0.15623 0.79087 0.773986 0 -0 0</pose>
        <scale>1 1 1</scale>
        <link name='link'>
          <pose frame=''>0.15623 0.79087 0.811486 0 -0 0</pose>
          <velocity>0 0 0 0 -0 0</velocity>
          <acceleration>0 0 0 0 -0 0</acceleration>
          <wrench>0 0 0 0 -0 0</wrench>
        </link>
      </model>
      <model name='ground_plane'>
        <pose frame=''>0 0 0 0 -0 0</pose>
        <scale>1 1 1</scale>
        <link name='link'>
          <pose frame=''>0 0 0 0 -0 0</pose>
          <velocity>0 0 0 0 -0 0</velocity>
          <acceleration>0 0 0 0 -0 0</acceleration>
          <wrench>0 0 0 0 -0 0</wrench>
        </link>
      </model>
      <model name='hammer'>
        <pose frame=''>0.298821 1.19413 0.790383 0 -0 0.734236</pose>
        <scale>1 1 1</scale>
        <link name='link'>
          <pose frame=''>0.298821 1.19413 0.790383 0 -0 0.734236</pose>
          <velocity>0 0 0 0 -0 0</velocity>
          <acceleration>0 0 0 0 -0 0</acceleration>
          <wrench>0 0 0 0 -0 0</wrench>
        </link>
      </model>
      <model name='sawyer'>
        <pose frame=''>-1.4e-05 8e-06 0.93 2.9e-05 5.4e-05 7e-06</pose>
        <scale>1 1 1</scale>
        <link name='base'>
          <pose frame=''>-1.4e-05 8e-06 0.93 2.9e-05 5.4e-05 7e-06</pose>
          <velocity>0 -3e-06 0 -1.1e-05 1e-06 0.012374</velocity>
          <acceleration>-3.5e-05 -0.020055 -1.3e-05 -0.022152 0.002205 -0.384722</acceleration>
          <wrench>-7.2e-05 -0.041487 -2.7e-05 0 -0 0</wrench>
        </link>
        <link name='head'>
          <pose frame=''>-4.2e-05 2.4e-05 1.3065 -2.4e-05 0.000104 2.3984</pose>
          <velocity>-2e-06 -1e-05 0 2.3e-05 -5e-06 0.000737</velocity>
          <acceleration>-0.010093 -0.030472 0.000162 0.049807 -0.000389 1.47414</acceleration>
          <wrench>-0.015941 -0.04813 0.000255 0 -0 0</wrench>
        </link>
        <link name='right_l0'>
          <pose frame=''>-1.4e-05 8e-06 1.01 -2.2e-05 9.6e-05 2.39879</pose>
          <velocity>-1e-06 -3e-06 0 2.1e-05 -4e-06 -9.9e-05</velocity>
          <acceleration>-0.000567 -0.007492 0.000163 2.08206 0.161998 -2.4832</acceleration>
          <wrench>-0.003019 -0.039868 0.000867 0 -0 0</wrench>
        </link>
        <link name='right_l1'>
          <pose frame=''>-0.093516 0.017976 1.24699 1.57085 1.15513 -0.742754</pose>
          <velocity>0 1e-06 0 1.1e-05 -1.7e-05 -9.8e-05</velocity>
          <acceleration>-0.009359 0.017946 -0.00414 1.56641 -0.953371 2.91787</acceleration>
          <wrench>-0.042163 0.080845 -0.018651 0 -0 0</wrench>
        </link>
        <link name='right_l2'>
          <pose frame=''>-0.284237 -0.000358 1.19046 -2.11481 0.675863 0.466224</pose>
          <velocity>0 2e-05 -4e-06 4.3e-05 -4.7e-05 -8e-05</velocity>
          <acceleration>0.01839 0.058765 -0.007269 -2.26214 0.23443 -1.99251</acceleration>
          <wrench>0.032091 0.102544 -0.012684 0 -0 0</wrench>
        </link>
        <link name='right_l3'>
          <pose frame=''>-0.44913 0.190045 1.11351 2.74901 -0.763382 -1.36714</pose>
          <velocity>1.9e-05 3.7e-05 -3e-06 5.4e-05 -1.5e-05 -5.2e-05</velocity>
          <acceleration>0.042042 0.064258 0.001995 0.247694 0.735296 1.90301</acceleration>
          <wrench>0.105514 0.161268 0.005006 0 -0 0</wrench>
        </link>
        <link name='right_l4'>
          <pose frame=''>-0.298288 0.269947 1.1634 -1.85861 -0.229464 -1.57873</pose>
          <velocity>2.2e-05 2.7e-05 4e-06 -0.000129 -2e-06 2e-06</velocity>
          <acceleration>0.044188 0.042173 0.010252 -1.57657 0.172908 -1.62637</acceleration>
          <wrench>0.049208 0.046964 0.011417 0 -0 0</wrench>
        </link>
        <link name='right_l5'>
          <pose frame=''>-0.043603 0.24341 1.05844 2.85574 0.231929 -0.259861</pose>
          <velocity>2.2e-05 1.3e-05 8e-06 -8e-05 3.5e-05 0.000159</velocity>
          <acceleration>0.037719 0.010473 0.015266 2.47476 0.256499 -1.5204</acceleration>
          <wrench>0.058936 0.016365 0.023853 0 -0 0</wrench>
        </link>
        <link name='right_l6'>
          <pose frame=''>-0.053448 0.324507 0.92993 -3.05345 -1.2917 1.28671</pose>
          <velocity>5e-06 2e-06 1e-06 -4e-05 0.000241 0.0001</velocity>
          <acceleration>0.007025 0.007755 -0.009271 -0.887061 -0.904879 -1.74495</acceleration>
          <wrench>0.006345 0.007004 -0.008374 0 -0 0</wrench>
        </link>
      </model>
      <light name='sun'>
        <pose frame=''>0 0 10 0 -0 0</pose>
      </light>
    </state>
  </world>
</sdf>
